<?xml version="1.0" ?>
<robot name="schunk_mpg_80" >
<!--
  <gazebo>
    <plugin filename="libcontrol.so" name="control">
    </plugin>
  </gazebo>
-->
  <link name="base">
    <visual>
      <origin xyz="0 0 0" rpy="0 0 0"/>
      <geometry>
        <mesh filename="package://schunk_description/meshes/mpg_80/visual/SCHUNK_MPG-80_BASE.dae"/>
      </geometry>
    </visual>
    <collision>
      <origin xyz="0 0.035 0" rpy="0 0 0"/>
      <geometry>
        <box size="0.08 0.07 0.042"/>
      </geometry>
    </collision>
    <collision>
      <origin xyz="-0.043 0.036 0.009" rpy="0 0 0"/>
      <geometry>
        <box size="0.006 0.012 0.012"/>
      </geometry>
    </collision>
    <collision>
      <origin xyz="-0.043 0.036 -0.009" rpy="0 0 0"/>
      <geometry>
        <box size="0.006 0.012 0.012"/>
      </geometry>
    </collision>
    <inertial>
      <mass value="0.96"/>
      <origin xyz="0 0.035 0" rpy="0 0 0"/>
      <inertia ixx="0.00053312" ixy="0" ixz="0" iyy="0.00065312" iyz="0" izz="0.000904"/>
    </inertial>
  </link>
  <joint name="l_finger_actuator" type="prismatic">
    <parent link="base"/>
    <child link="l_finger"/>
    <origin xyz="0 0 0" rpy="0 0 0"/>
    <axis xyz="1 0 0"/>
    <limit effort="190.0" lower="0" upper="0.014" velocity="0.2333"/>
    <dynamics damping="0" friction="0"/>
  </joint>
  <link name="l_finger">
    <visual>
      <origin xyz="0 0 0" rpy="0 0 0"/>
      <geometry>
        <mesh filename="package://schunk_description/meshes/mpg_80/visual/SCHUNK_MPG-80_LEFT_FINGER.dae"/>
      </geometry>
    </visual>
    <collision>
      <origin xyz="-0.0205 0.0798 0" rpy="0 0 0"/>
      <geometry>
        <box size="0.012 0.0194 0.024"/>
      </geometry>
    </collision>
    <inertial>
      <mass value="0.12"/>
      <origin xyz="-0.0205 0.0798 0" rpy="0 0 0" />
      <inertia ixx="0.0000095236" ixy="0" ixz="0" iyy="0.0000072" iyz="0" izz="0.0000052036"/>
    </inertial>
  </link>
  <joint name="r_finger_actuator" type="prismatic">
    <parent link="base"/>
    <child link="r_finger"/>
    <origin xyz="0 0 0" rpy="0 0 0"/>
    <axis xyz="1 0 0"/>
    <limit effort="190.0" lower="-0.014" upper="0" velocity="0.2333"/>
    <dynamics damping="0" friction="0"/>
  </joint>
  <link name="r_finger">
    <visual>
      <origin xyz="0 0 0" rpy="0 0 0"/>
      <geometry>
        <mesh filename="package://schunk_description/meshes/mpg_80/visual/SCHUNK_MPG-80_RIGHT_FINGER.dae"/>
      </geometry>
    </visual>
    <collision>
      <origin xyz="0.0205 0.0798 0" rpy="0 0 0"/>
      <geometry>
        <box size="0.012 0.0194 0.024"/>
      </geometry>
    </collision>
    <inertial>
      <mass value="0.12"/>
      <origin xyz="0.0205 0.0798 0" rpy="0 0 0"/>
      <inertia ixx="0.0000095236" ixy="0" ixz="0" iyy="0.0000072" iyz="0" izz="0.0000052036"/>
    </inertial>
  </link>
</robot>
